<?xml version="1.0" encoding="utf-8"?>
<robot name="probot_g750" xmlns:xacro="http://ros.org/wiki/xacro">

  <xacro:property name="M_PI" value="3.1415926536"/>

  <link
    name="base_link">
    <inertial>
      <origin
        xyz="-0.012011 4.3993E-05 0.067319"
        rpy="0 0 0" />
      <mass
        value="3.232" />
      <inertia
        ixx="0.010633"
        ixy="9.4437E-06"
        ixz="-0.00081586"
        iyy="0.013753"
        iyz="-3.781E-06"
        izz="0.012504" />
    </inertial>
    <visual>
      <origin
        xyz="0 0 0"
        rpy="0 0 0" />
      <geometry>
        <mesh
          filename="package://probot_description/meshes/PROBOT_G750/base_link.STL" />
      </geometry>
      <material
        name="">
        <color
          rgba="0.79216 0.81961 0.93333 1" />
      </material>
    </visual>
    <collision>
      <origin
        xyz="0 0 0"
        rpy="0 0 0" />
      <geometry>
        <mesh
          filename="package://probot_description/meshes/PROBOT_G750/base_link.STL" />
      </geometry>
    </collision>
  </link>
  <link
    name="link_1">
    <inertial>
      <origin
        xyz="0.013953 0.010956 0.093071"
        rpy="0 0 0" />
      <mass
        value="2.1229" />
      <inertia
        ixx="0.0086805"
        ixy="-0.00023668"
        ixz="-0.0014884"
        iyy="0.0092115"
        iyz="-0.00078177"
        izz="0.0044963" />
    </inertial>
    <visual>
      <origin
        xyz="0 0 0"
        rpy="0 0 0" />
      <geometry>
        <mesh
          filename="package://probot_description/meshes/PROBOT_G750/link_1.STL" />
      </geometry>
      <material
        name="">
        <color
          rgba="0.79216 0.81961 0.93333 1" />
      </material>
    </visual>
    <collision>
      <origin
        xyz="0 0 0"
        rpy="0 0 0" />
      <geometry>
        <mesh
          filename="package://probot_description/meshes/PROBOT_G750/link_1.STL" />
      </geometry>
    </collision>
  </link>
  <joint
    name="joint_1"
    type="revolute">
    <origin
      xyz="0 0 0.14875"
      rpy="0 0 0" />
    <parent
      link="base_link" />
    <child
      link="link_1" />
    <axis
      xyz="0 0 1" />
    <limit
      lower="-2.88"
      upper="2.88"
      effort="100"
      velocity="2.08" />
  </joint>
  <link
    name="link_2">
    <inertial>
      <origin
        xyz="-0.016908 0.11367 0.040208"
        rpy="0 0 0" />
      <mass
        value="1.9315" />
      <inertia
        ixx="0.019807"
        ixy="0.0017059"
        ixz="3.2581E-05"
        iyy="0.0025044"
        iyz="-5.2608E-05"
        izz="0.021346" />
    </inertial>
    <visual>
      <origin
        xyz="0 0 0"
        rpy="0 0 0" />
      <geometry>
        <mesh
          filename="package://probot_description/meshes/PROBOT_G750/link_2.STL" />
      </geometry>
      <material
        name="">
        <color
          rgba="0.79216 0.81961 0.93333 1" />
      </material>
    </visual>
    <collision>
      <origin
        xyz="0 0 0"
        rpy="0 0 0" />
      <geometry>
        <mesh
          filename="package://probot_description/meshes/PROBOT_G750/link_2.STL" />
      </geometry>
    </collision>
  </link>
  <joint
    name="joint_2"
    type="revolute">
    <origin
      xyz="0.03117 -0.02376 0.145"
      rpy="${M_PI/2} 0 0" />
    <parent
      link="link_1" />
    <child
      link="link_2" />
    <axis
      xyz="0 0 1" />
    <limit
      lower="-1.22"
      upper="1.22"
      effort="100"
      velocity="4.36" />
  </joint>
  <link
    name="link_3">
    <inertial>
      <origin
        xyz="0.022453 -0.0083389 -0.04248"
        rpy="0 0 0" />
      <mass
        value="1.3008" />
      <inertia
        ixx="0.0022189"
        ixy="-7.8328E-05"
        ixz="-0.00011736"
        iyy="0.0026226"
        iyz="4.3783E-05"
        izz="0.0031838" />
    </inertial>
    <visual>
      <origin
        xyz="0 0 0"
        rpy="0 0 0" />
      <geometry>
        <mesh
          filename="package://probot_description/meshes/PROBOT_G750/link_3.STL" />
      </geometry>
      <material
        name="">
        <color
          rgba="0.79216 0.81961 0.93333 1" />
      </material>
    </visual>
    <collision>
      <origin
        xyz="0 0 0"
        rpy="0 0 0" />
      <geometry>
        <mesh
          filename="package://probot_description/meshes/PROBOT_G750/link_3.STL" />
      </geometry>
    </collision>
  </link>
  <joint
    name="joint_3"
    type="revolute">
    <origin
      xyz="-0.018881 0.25 0.0095"
      rpy="0 0 0" />
    <parent
      link="link_2" />
    <child
      link="link_3" />
    <axis
      xyz="0 0 1" />
    <limit
      lower="-0.52"
      upper="3.66"
      effort="100"
      velocity="4.36" />
  </joint>
  <link
    name="link_4">
    <inertial>
      <origin
        xyz="0.00010655 -0.0010532 0.091532"
        rpy="0 0 0" />
      <mass
        value="1.0774" />
      <inertia
        ixx="0.004115"
        ixy="1.4418E-06"
        ixz="-8.5329E-06"
        iyy="0.0041598"
        iyz="7.5121E-05"
        izz="0.00099177" />
    </inertial>
    <visual>
      <origin
        xyz="0 0 0"
        rpy="0 0 0" />
      <geometry>
        <mesh
          filename="package://probot_description/meshes/PROBOT_G750/link_4.STL" />
      </geometry>
      <material
        name="">
        <color
          rgba="0.79216 0.81961 0.93333 1" />
      </material>
    </visual>
    <collision>
      <origin
        xyz="0 0 0"
        rpy="0 0 0" />
      <geometry>
        <mesh
          filename="package://probot_description/meshes/PROBOT_G750/link_4.STL" />
      </geometry>
    </collision>
  </link>
  <joint
    name="joint_4"
    type="revolute">
    <origin
      xyz="0.09 0 -0.038448"
      rpy="${M_PI/2} 0 ${M_PI/2}" />
    <parent
      link="link_3" />
    <child
      link="link_4" />
    <axis
      xyz="0 0 1" />
    <limit
      lower="-2.35"
      upper="2.35"
      effort="100"
      velocity="6.28" />
  </joint>
  <link
    name="link_5">
    <inertial>
      <origin
        xyz="-0.0039044 -0.066494 -0.0033948"
        rpy="0 0 0" />
      <mass
        value="0.49363" />
      <inertia
        ixx="0.0011443"
        ixy="-2.806E-05"
        ixz="-5.1028E-08"
        iyy="0.00052555"
        iyz="3.1271E-06"
        izz="0.0010692" />
    </inertial>
    <visual>
      <origin
        xyz="0 0 0"
        rpy="0 0 0" />
      <geometry>
        <mesh
          filename="package://probot_description/meshes/PROBOT_G750/link_5.STL" />
      </geometry>
      <material
        name="">
        <color
          rgba="0.79216 0.81961 0.93333 1" />
      </material>
    </visual>
    <collision>
      <origin
        xyz="0 0 0"
        rpy="0 0 0" />
      <geometry>
        <mesh
          filename="package://probot_description/meshes/PROBOT_G750/link_5.STL" />
      </geometry>
    </collision>
  </link>
  <joint
    name="joint_5"
    type="revolute">
    <origin
      xyz="0 0 0.1575"
      rpy="-${M_PI/2} -${M_PI/2} 0" />
    <parent
      link="link_4" />
    <child
      link="link_5" />
    <axis
      xyz="0 0 1" />
    <limit
      lower="-0.17"
      upper="3.14"
      effort="100"
      velocity="3.49" />
  </joint>
  <link
    name="link_6">
    <inertial>
      <origin
        xyz="4.1386E-09 1.6596E-09 -0.017711"
        rpy="0 0 0" />
      <mass
        value="0.054791" />
      <inertia
        ixx="1.248E-05"
        ixy="3.7714E-19"
        ixz="-2.2661E-12"
        iyy="1.248E-05"
        iyz="-9.0874E-13"
        izz="1.3489E-05" />
    </inertial>
    <visual>
      <origin
        xyz="0 0 0"
        rpy="0 0 0" />
      <geometry>
        <mesh
          filename="package://probot_description/meshes/PROBOT_G750/link_6.STL" />
      </geometry>
      <material
        name="">
        <color
          rgba="0.79216 0.81961 0.93333 1" />
      </material>
    </visual>
    <collision>
      <origin
        xyz="0 0 0"
        rpy="0 0 0" />
      <geometry>
        <mesh
          filename="package://probot_description/meshes/PROBOT_G750/link_6.STL" />
      </geometry>
    </collision>
  </link>
  <joint
    name="joint_6"
    type="revolute">
    <origin
      xyz="0 -0.14876 0"
      rpy="${M_PI/2} 0 0" />
    <parent
      link="link_5" />
    <child
      link="link_6" />
    <axis
      xyz="0 0 1" />
    <limit
      lower="-3.14"
      upper="3.14"
      effort="100"
      velocity="6.28" />
  </joint>

  <link name="tool0"/>
  <joint name="joint_tool0" type="fixed">
    <origin xyz="0 0 0" rpy="${M_PI} 0 0" />
    <parent link="link_6" />
    <child link="tool0" />
  </joint>

</robot>
